{
  "artifacts": [],
  "command": "do_experiment",
  "experiment": {
    "base_dir": "/home/enterprise.internal.city.ac.uk/acvn728/MScFinalProject",
    "dependencies": [
      "numpy==1.15.2",
      "sacred==0.7.4",
      "tensorflow-gpu==1.11.0"
    ],
    "mainfile": "main.py",
    "name": "UNet_Speech_Separation",
    "repositories": [],
    "sources": [
      [
        "audio_models.py",
        "_sources/audio_models_f18f61db39939ae190ffb11515e74407.py"
      ],
      [
        "dataset.py",
        "_sources/dataset_a83ad44a54b843a850f6c265244adb8b.py"
      ],
      [
        "main.py",
        "_sources/main_86f3cd032ec613acd4e5a09a8dfccab4.py"
      ],
      [
        "train.py",
        "_sources/train_ac3950bf487bd618b79d27ec5ead97fb.py"
      ]
    ]
  },
  "fail_trace": [
    "Traceback (most recent call last):\n",
    "  File \"/home/enterprise.internal.city.ac.uk/acvn728/.local/lib/python3.5/site-packages/sacred/config/captured_function.py\", line 46, in captured_function\n    result = wrapped(*args, **kwargs)\n",
    "  File \"main.py\", line 127, in do_experiment\n    restorer.restore(sess, checkpoint)\n",
    "  File \"/home/enterprise.internal.city.ac.uk/acvn728/.local/lib/python3.5/site-packages/tensorflow/python/training/saver.py\", line 1530, in restore\n    + compat.as_text(save_path))\n",
    "ValueError: The passed save_path is not a valid checkpoint: /home/enterprise.internal.city.ac.uk/acvn728/checkpoints/114/114-473\n"
  ],
  "heartbeat": "2018-10-12T07:07:02.843078",
  "host": {
    "ENV": {},
    "cpu": "AMD Ryzen 7 1700 Eight-Core Processor",
    "gpus": {
      "driver_version": "396.44",
      "gpus": [
        {
          "model": "GeForce GTX 1080 Ti",
          "persistence_mode": false,
          "total_memory": 11177
        },
        {
          "model": "GeForce GTX 1080 Ti",
          "persistence_mode": false,
          "total_memory": 11178
        }
      ]
    },
    "hostname": "africa",
    "os": [
      "Linux",
      "Linux-4.4.0-137-generic-x86_64-with-Ubuntu-16.04-xenial"
    ],
    "python_version": "3.5.2"
  },
  "meta": {
    "command": "do_experiment",
    "options": {
      "--beat_interval": null,
      "--capture": null,
      "--comment": null,
      "--debug": false,
      "--enforce_clean": false,
      "--file_storage": null,
      "--force": false,
      "--help": false,
      "--loglevel": null,
      "--mongo_db": null,
      "--name": null,
      "--pdb": false,
      "--print_config": false,
      "--priority": null,
      "--queue": false,
      "--sql": null,
      "--tiny_db": null,
      "--unobserved": false,
      "COMMAND": null,
      "UPDATE": [],
      "help": false,
      "with": false
    }
  },
  "resources": [],
  "result": null,
  "start_time": "2018-10-12T07:04:19.353449",
  "status": "FAILED",
  "stop_time": "2018-10-12T07:07:02.856725"
}